Workbook
Name Input_Requirement_IDs: Input_Template!$A$2:$A$1000
Name Staff_Name_Dropdown: #REF!
Name Staff_Name_List: #REF!

Sheet README
A1: Sample
A2: Below are samples on how to fill up the tabs.
A3: How to use this workbook: | B3: 1) Start in Input_Template and complete one row for each class.
B4: 2) Choose from the dropdown lists. Do not type over the Staff ID cells; they fill automatically.
B5: 3) Requirement ID uses Programme-XX format, for example AAI-01. Student Group Code should be P1, P2, P3, P4, or P5.
B6: 4) In Remarks_(optional), type the same Requirement ID used in Input_Template. A red Requirement ID means it does not exist in Input_Template.
B7: 5) Do not edit the DB tabs unless you need to update the programme, module, staff, or dropdown lists.
A8: Input_Template
A9: Requirement ID | B9: Programme | C9: Year | D9: Student Group Code | E9: Module Code | F9: Class Type | G9: Duration Hours | H9: Sessions Per Week | I9: Delivery Mode | J9: Venue Type Required | K9: Staff 1 Name | L9: Staff 1 ID | M9: Staff 2 Name | N9: Staff 2 ID | O9: Staff 3 Name | P9: Staff 3 ID | Q9: Staff 4 Name | R9: Staff 4 ID
A10: AAI-01 | B10: AAI | C10: 1 | D10: P1 | E10: AAI1001 | F10: Lecture | G10: 2 | H10: 1 | I10: Face-to-face | J10: Lectorial | K10: AARON TAN | L10: G22207 | M10: AARON YEO SULUN | N10: H50949
A11: AAI-02 | B11: AAI | C11: 2 | D11: P2 | E11: AAI2002 | F11: Tutorial | G11: 2 | H11: 1 | I11: Face-to-face | J11: Seminar Room | K11: ABDUL JABBAR ABDULLAH | L11: H52030
A12: AAI-03 | B12: AAI | C12: 3 | D12: P1 | E12: AAI3008 | F12: Laboratory | G12: 2 | H12: 1 | I12: Face-to-face | J12: Computer Lab | K12: ABID ALI | L12: A101849 | M12: ABIGAIL ELIZABETH ROCHE | N12: H51758 | O12: ABROL AKSHITA | P12: A103173
A13: Dropdown sources | B13: Programme: DB_Programme | Module Code: DB_Modules | Staff Name/ID: DB_Staff | Other options: DB_Options
A15: Remarks_(optional)
A16: Requirement ID | B16: Start Week | C16: End Week | D16: Week Pattern | E16: Custom Weeks | F16: Preferred Days | G16: Avoid Days | H16: Fixed Day | I16: Fixed Start Time | J16: Fixed End Time | K16: Remarks | L16: Priority | M16: Common Module? | N16: Shared Session Group ID | O16: Combined With Programmes | P16: Remarks
A17: AAI-01 | B17: 1 | C17: 13 | D17: Weekly | F17: Tuesday,Thursday | H17: Monday | I17: 09:00 | J17: 11:00 | K17: Large cohort anchor lecture. | L17: Normal | M17: No | P17: Large cohort anchor lecture.
A18: AAI-02 | B18: 1 | C18: 13 | D18: Odd | F18: Tuesday,Thursday | G18: Friday | K18: Tutorial split; suitable for repeated group scheduling. | L18: Normal | M18: No | P18: Tutorial split; suitable for repeated group scheduling.
A19: AAI-03 | B19: 1 | C19: 13 | D19: Custom | E19: 3,6,9,12 | F19: Tuesday,Thursday | G19: Friday | K19: Custom teaching weeks for lab rotations. | L19: Normal | M19: No | P19: Custom teaching weeks for lab rotations.

Sheet Input_Template
A1: Requirement ID | B1: Programme | C1: Year | D1: Student Group Code | E1: Module Code | F1: Class Type | G1: Duration Hours | H1: Sessions Per Week | I1: Delivery Mode | J1: Venue Type Required | K1: Staff 1 Name | L1: Staff 1 ID | M1: Staff 2 Name | N1: Staff 2 ID | O1: Staff 3 Name | P1: Staff 3 ID | Q1: Staff 4 Name | R1: Staff 4 ID
A2: AAI-01 | B2: AAI | C2: 1 | D2: P1 | E2: AAI1001 | F2: Lecture | G2: 2 | H2: 1 | I2: Face-to-face | J2: Lectorial | K2: AARON TAN | L2: =IF(K2="","",IFERROR(INDEX(DB_Staff!$A:$A,MATCH(K2,DB_Staff!$B:$B,0)),"")) -> G22207 | M2: AARON YEO SULUN | N2: =IF(M2="","",IFERROR(INDEX(DB_Staff!$A:$A,MATCH(M2,DB_Staff!$B:$B,0)),"")) -> H50949 | P2: =IF(O2="","",IFERROR(INDEX(DB_Staff!$A:$A,MATCH(O2,DB_Staff!$B:$B,0)),"")) | R2: =IF(Q2="","",IFERROR(INDEX(DB_Staff!$A:$A,MATCH(Q2,DB_Staff!$B:$B,0)),""))
A3: AAI-02 | B3: AAI | C3: 2 | D3: P2 | E3: AAI2002 | F3: Tutorial | G3: 2 | H3: 1 | I3: Face-to-face | J3: Seminar Room | K3: ABDUL JABBAR ABDULLAH | L3: =IF(K3="","",IFERROR(INDEX(DB_Staff!$A:$A,MATCH(K3,DB_Staff!$B:$B,0)),"")) -> H52030 | N3: =IF(M3="","",IFERROR(INDEX(DB_Staff!$A:$A,MATCH(M3,DB_Staff!$B:$B,0)),"")) | P3: =IF(O3="","",IFERROR(INDEX(DB_Staff!$A:$A,MATCH(O3,DB_Staff!$B:$B,0)),"")) | R3: =IF(Q3="","",IFERROR(INDEX(DB_Staff!$A:$A,MATCH(Q3,DB_Staff!$B:$B,0)),""))
A4: AAI-03 | B4: AAI | C4: 3 | D4: P1 | E4: AAI3008 | F4: Laboratory | G4: 2 | H4: 1 | I4: Face-to-face | J4: Computer Lab | K4: ABID ALI | L4: =IF(K4="","",IFERROR(INDEX(DB_Staff!$A:$A,MATCH(K4,DB_Staff!$B:$B,0)),"")) -> A101849 | M4: ABIGAIL ELIZABETH ROCHE | N4: =IF(M4="","",IFERROR(INDEX(DB_Staff!$A:$A,MATCH(M4,DB_Staff!$B:$B,0)),"")) -> H51758 | O4: ABROL AKSHITA | P4: =IF(O4="","",IFERROR(INDEX(DB_Staff!$A:$A,MATCH(O4,DB_Staff!$B:$B,0)),"")) -> A103173 | R4: =IF(Q4="","",IFERROR(INDEX(DB_Staff!$A:$A,MATCH(Q4,DB_Staff!$B:$B,0)),""))
A5: AAI-04 | B5: AAI | C5: 3 | D5: P2 | E5: AAI4001 | F5: Workshop | G5: 1 | H5: 2 | I5: Hybrid | J5: Seminar Room | K5: ADRIEL YEO CI LIN | L5: =IF(K5="","",IFERROR(INDEX(DB_Staff!$A:$A,MATCH(K5,DB_Staff!$B:$B,0)),"")) -> A101516 | N5: =IF(M5="","",IFERROR(INDEX(DB_Staff!$A:$A,MATCH(M5,DB_Staff!$B:$B,0)),"")) | P5: =IF(O5="","",IFERROR(INDEX(DB_Staff!$A:$A,MATCH(O5,DB_Staff!$B:$B,0)),"")) | R5: =IF(Q5="","",IFERROR(INDEX(DB_Staff!$A:$A,MATCH(Q5,DB_Staff!$B:$B,0)),""))
A6: AAI-05 | B6: AAI | C6: 3 | D6: P1 | E6: AAI4002A | F6: Online | G6: 1 | H6: 1 | I6: Online | J6: Virtual | K6: AARON TAN | L6: =IF(K6="","",IFERROR(INDEX(DB_Staff!$A:$A,MATCH(K6,DB_Staff!$B:$B,0)),"")) -> G22207 | N6: =IF(M6="","",IFERROR(INDEX(DB_Staff!$A:$A,MATCH(M6,DB_Staff!$B:$B,0)),"")) | P6: =IF(O6="","",IFERROR(INDEX(DB_Staff!$A:$A,MATCH(O6,DB_Staff!$B:$B,0)),"")) | R6: =IF(Q6="","",IFERROR(INDEX(DB_Staff!$A:$A,MATCH(Q6,DB_Staff!$B:$B,0)),""))
A7: ACC-01 | B7: ACC | C7: 1 | D7: P1 | E7: ACC1023 | F7: Lecture | G7: 2 | H7: 1 | I7: Face-to-face | J7: Lectorial | K7: AHMAD ZUHAIRI BIN SAAT | L7: =IF(K7="","",IFERROR(INDEX(DB_Staff!$A:$A,MATCH(K7,DB_Staff!$B:$B,0)),"")) -> G22213 | M7: AISHWARIYAA RAMAKANTHAN | N7: =IF(M7="","",IFERROR(INDEX(DB_Staff!$A:$A,MATCH(M7,DB_Staff!$B:$B,0)),"")) -> H52007 | P7: =IF(O7="","",IFERROR(INDEX(DB_Staff!$A:$A,MATCH(O7,DB_Staff!$B:$B,0)),"")) | R7: =IF(Q7="","",IFERROR(INDEX(DB_Staff!$A:$A,MATCH(Q7,DB_Staff!$B:$B,0)),""))
A8: ACC-02 | B8: ACC | C8: 1 | D8: P1 | E8: ACC1024 | F8: Tutorial | G8: 2 | H8: 1 | I8: Face-to-face | J8: Seminar Room | K8: AKASHDEEP SINGH BENIWAL | L8: =IF(K8="","",IFERROR(INDEX(DB_Staff!$A:$A,MATCH(K8,DB_Staff!$B:$B,0)),"")) -> G22319 | N8: =IF(M8="","",IFERROR(INDEX(DB_Staff!$A:$A,MATCH(M8,DB_Staff!$B:$B,0)),"")) | P8: =IF(O8="","",IFERROR(INDEX(DB_Staff!$A:$A,MATCH(O8,DB_Staff!$B:$B,0)),"")) | R8: =IF(Q8="","",IFERROR(INDEX(DB_Staff!$A:$A,MATCH(Q8,DB_Staff!$B:$B,0)),""))
A9: ACC-03 | B9: ACC | C9: 1 | D9: P2 | E9: ACC1025 | F9: Laboratory | G9: 2 | H9: 1 | I9: Face-to-face | J9: Computer Lab | K9: ALAGESAN MUTHUKUMARASAMY | L9: =IF(K9="","",IFERROR(INDEX(DB_Staff!$A:$A,MATCH(K9,DB_Staff!$B:$B,0)),"")) -> A101929 | M9: ALDEN CH’NG CHUN YANG | N9: =IF(M9="","",IFERROR(INDEX(DB_Staff!$A:$A,MATCH(M9,DB_Staff!$B:$B,0)),"")) -> G22231 | O9: ALEJANDRA ACEVEDO-FANI | P9: =IF(O9="","",IFERROR(INDEX(DB_Staff!$A:$A,MATCH(O9,DB_Staff!$B:$B,0)),"")) -> G22314 | R9: =IF(Q9="","",IFERROR(INDEX(DB_Staff!$A:$A,MATCH(Q9,DB_Staff!$B:$B,0)),""))
A10: ACC-04 | B10: ACC | C10: 1 | D10: P1 | E10: ACC1026 | F10: Workshop | G10: 1 | H10: 2 | I10: Hybrid | J10: Seminar Room | K10: ALESSANDRO FERGNANI | L10: =IF(K10="","",IFERROR(INDEX(DB_Staff!$A:$A,MATCH(K10,DB_Staff!$B:$B,0)),"")) -> H51820 | N10: =IF(M10="","",IFERROR(INDEX(DB_Staff!$A:$A,MATCH(M10,DB_Staff!$B:$B,0)),"")) | P10: =IF(O10="","",IFERROR(INDEX(DB_Staff!$A:$A,MATCH(O10,DB_Staff!$B:$B,0)),"")) | R10: =IF(Q10="","",IFERROR(INDEX(DB_Staff!$A:$A,MATCH(Q10,DB_Staff!$B:$B,0)),""))
A11: ACC-05 | B11: ACC | C11: 3 | D11: P1 | E11: ACC3001A | F11: Online | G11: 1 | H11: 1 | I11: Online | J11: Virtual | K11: ALEX LEE KHUEH HOCK | L11: =IF(K11="","",IFERROR(INDEX(DB_Staff!$A:$A,MATCH(K11,DB_Staff!$B:$B,0)),"")) -> H50358 | N11: =IF(M11="","",IFERROR(INDEX(DB_Staff!$A:$A,MATCH(M11,DB_Staff!$B:$B,0)),"")) | P11: =IF(O11="","",IFERROR(INDEX(DB_Staff!$A:$A,MATCH(O11,DB_Staff!$B:$B,0)),"")) | R11: =IF(Q11="","",IFERROR(INDEX(DB_Staff!$A:$A,MATCH(Q11,DB_Staff!$B:$B,0)),""))
A12: ASE-01 | B12: ASE | C12: 1 | D12: P1 | E12: ASE1101 | F12: Lecture | G12: 2 | H12: 1 | I12: Face-to-face | J12: Lectorial | K12: ALEXANDER W. KOCH | L12: =IF(K12="","",IFERROR(INDEX(DB_Staff!$A:$A,MATCH(K12,DB_Staff!$B:$B,0)),"")) -> G13051 | M12: ALEXANDER WIRIANSKI | N12: =IF(M12="","",IFERROR(INDEX(DB_Staff!$A:$A,MATCH(M12,DB_Staff!$B:$B,0)),"")) -> A101627 | P12: =IF(O12="","",IFERROR(INDEX(DB_Staff!$A:$A,MATCH(O12,DB_Staff!$B:$B,0)),"")) | R12: =IF(Q12="","",IFERROR(INDEX(DB_Staff!$A:$A,MATCH(Q12,DB_Staff!$B:$B,0)),""))
A13: ASE-02 | B13: ASE | C13: 1 | D13: P2 | E13: ASE1201 | F13: Tutorial | G13: 2 | H13: 1 | I13: Face-to-face | J13: Seminar Room | K13: ALFRED WHANG SHANG JIN | L13: =IF(K13="","",IFERROR(INDEX(DB_Staff!$A:$A,MATCH(K13,DB_Staff!$B:$B,0)),"")) -> H51712 | N13: =IF(M13="","",IFERROR(INDEX(DB_Staff!$A:$A,MATCH(M13,DB_Staff!$B:$B,0)),"")) | P13: =IF(O13="","",IFERROR(INDEX(DB_Staff!$A:$A,MATCH(O13,DB_Staff!$B:$B,0)),"")) | R13: =IF(Q13="","",IFERROR(INDEX(DB_Staff!$A:$A,MATCH(Q13,DB_Staff!$B:$B,0)),""))
A14: ASE-03 | B14: ASE | C14: 1 | D14: P1 | E14: ASE1202 | F14: Laboratory | G14: 2 | H14: 1 | I14: Face-to-face | J14: Computer Lab | K14: ALINE TEH HOOI MING | L14: =IF(K14="","",IFERROR(INDEX(DB_Staff!$A:$A,MATCH(K14,DB_Staff!$B:$B,0)),"")) -> H52293 | M14: ALLEN CHEONG JEE MUN | N14: =IF(M14="","",IFERROR(INDEX(DB_Staff!$A:$A,MATCH(M14,DB_Staff!$B:$B,0)),"")) -> H51765 | O14: ALLISON CHING CHO HUI | P14: =IF(O14="","",IFERROR(INDEX(DB_Staff!$A:$A,MATCH(O14,DB_Staff!$B:$B,0)),"")) -> H52155 | R14: =IF(Q14="","",IFERROR(INDEX(DB_Staff!$A:$A,MATCH(Q14,DB_Staff!$B:$B,0)),""))
A15: ASE-04 | B15: ASE | C15: 2 | D15: P2 | E15: ASE2207 | F15: Workshop | G15: 1 | H15: 2 | I15: Hybrid | J15: Seminar Room | K15: ALOK PRAKASH | L15: =IF(K15="","",IFERROR(INDEX(DB_Staff!$A:$A,MATCH(K15,DB_Staff!$B:$B,0)),"")) -> H51419 | N15: =IF(M15="","",IFERROR(INDEX(DB_Staff!$A:$A,MATCH(M15,DB_Staff!$B:$B,0)),"")) | P15: =IF(O15="","",IFERROR(INDEX(DB_Staff!$A:$A,MATCH(O15,DB_Staff!$B:$B,0)),"")) | R15: =IF(Q15="","",IFERROR(INDEX(DB_Staff!$A:$A,MATCH(Q15,DB_Staff!$B:$B,0)),""))
A16: ASE-05 | B16: ASE | C16: 2 | D16: P1 | E16: ASE2210 | F16: Online | G16: 1 | H16: 1 | I16: Online | J16: Virtual | K16: ALVIN YEO HONG HEE | L16: =IF(K16="","",IFERROR(INDEX(DB_Staff!$A:$A,MATCH(K16,DB_Staff!$B:$B,0)),"")) -> G22155 | N16: =IF(M16="","",IFERROR(INDEX(DB_Staff!$A:$A,MATCH(M16,DB_Staff!$B:$B,0)),"")) | P16: =IF(O16="","",IFERROR(INDEX(DB_Staff!$A:$A,MATCH(O16,DB_Staff!$B:$B,0)),"")) | R16: =IF(Q16="","",IFERROR(INDEX(DB_Staff!$A:$A,MATCH(Q16,DB_Staff!$B:$B,0)),""))
A17: ATM-01 | B17: ATM | C17: 1 | D17: P1 | E17: ATM1104 | F17: Lecture | G17: 2 | H17: 1 | I17: Face-to-face | J17: Lectorial | K17: ALWYN LEE CHEE YUAN | L17: =IF(K17="","",IFERROR(INDEX(DB_Staff!$A:$A,MATCH(K17,DB_Staff!$B:$B,0)),"")) -> G22078 | M17: ALYSSA STEFANIE PETER | N17: =IF(M17="","",IFERROR(INDEX(DB_Staff!$A:$A,MATCH(M17,DB_Staff!$B:$B,0)),"")) -> H51855 | P17: =IF(O17="","",IFERROR(INDEX(DB_Staff!$A:$A,MATCH(O17,DB_Staff!$B:$B,0)),"")) | R17: =IF(Q17="","",IFERROR(INDEX(DB_Staff!$A:$A,MATCH(Q17,DB_Staff!$B:$B,0)),""))
A18: ATM-02 | B18: ATM | C18: 1 | D18: P1 | E18: ATM1105 | F18: Tutorial | G18: 2 | H18: 1 | I18: Face-to-face | J18: Seminar Room | K18: AMARJIT KAUR SARDUL SINGH | L18: =IF(K18="","",IFERROR(INDEX(DB_Staff!$A:$A,MATCH(K18,DB_Staff!$B:$B,0)),"")) -> H50469 | N18: =IF(M18="","",IFERROR(INDEX(DB_Staff!$A:$A,MATCH(M18,DB_Staff!$B:$B,0)),"")) | P18: =IF(O18="","",IFERROR(INDEX(DB_Staff!$A:$A,MATCH(O18,DB_Staff!$B:$B,0)),"")) | R18: =IF(Q18="","",IFERROR(INDEX(DB_Staff!$A:$A,MATCH(Q18,DB_Staff!$B:$B,0)),""))
A19: ATM-03 | B19: ATM | C19: 1 | D19: P2 | E19: ATM1106 | F19: Laboratory | G19: 2 | H19: 1 | I19: Face-to-face | J19: Computer Lab | K19: AN HUI | L19: =IF(K19="","",IFERROR(INDEX(DB_Staff!$A:$A,MATCH(K19,DB_Staff!$B:$B,0)),"")) -> A88485 | M19: ANDREAS HERKERSDORF | N19: =IF(M19="","",IFERROR(INDEX(DB_Staff!$A:$A,MATCH(M19,DB_Staff!$B:$B,0)),"")) -> G22165 | O19: ANDREAS HERMANUTZ | P19: =IF(O19="","",IFERROR(INDEX(DB_Staff!$A:$A,MATCH(O19,DB_Staff!$B:$B,0)),"")) -> G22047 | R19: =IF(Q19="","",IFERROR(INDEX(DB_Staff!$A:$A,MATCH(Q19,DB_Staff!$B:$B,0)),""))
A20: ATM-04 | B20: ATM | C20: 3 | D20: P1 | E20: ATM3100A | F20: Workshop | G20: 1 | H20: 2 | I20: Hybrid | J20: Seminar Room | K20: ANDREAS JENTYS | L20: =IF(K20="","",IFERROR(INDEX(DB_Staff!$A:$A,MATCH(K20,DB_Staff!$B:$B,0)),"")) -> G13044 | N20: =IF(M20="","",IFERROR(INDEX(DB_Staff!$A:$A,MATCH(M20,DB_Staff!$B:$B,0)),"")) | P20: =IF(O20="","",IFERROR(INDEX(DB_Staff!$A:$A,MATCH(O20,DB_Staff!$B:$B,0)),"")) | R20: =IF(Q20="","",IFERROR(INDEX(DB_Staff!$A:$A,MATCH(Q20,DB_Staff!$B:$B,0)),""))
A21: ATM-05 | B21: ATM | C21: 3 | D21: P1 | E21: ATM3100B | F21: Online | G21: 1 | H21: 1 | I21: Online | J21: Virtual | K21: ANDREW GARRARD | L21: =IF(K21="","",IFERROR(INDEX(DB_Staff!$A:$A,MATCH(K21,DB_Staff!$B:$B,0)),"")) -> G22156 | N21: =IF(M21="","",IFERROR(INDEX(DB_Staff!$A:$A,MATCH(M21,DB_Staff!$B:$B,0)),"")) | P21: =IF(O21="","",IFERROR(INDEX(DB_Staff!$A:$A,MATCH(O21,DB_Staff!$B:$B,0)),"")) | R21: =IF(Q21="","",IFERROR(INDEX(DB_Staff!$A:$A,MATCH(Q21,DB_Staff!$B:$B,0)),""))
A22: BAC-01 | B22: BAC | C22: 2 | D22: P1 | E22: BAC2001 | F22: Lecture | G22: 2 | H22: 1 | I22: Face-to-face | J22: Lectorial | K22: AARON TAN | L22: =IF(K22="","",IFERROR(INDEX(DB_Staff!$A:$A,MATCH(K22,DB_Staff!$B:$B,0)),"")) -> G22207 | M22: ANDY TAN | N22: =IF(M22="","",IFERROR(INDEX(DB_Staff!$A:$A,MATCH(M22,DB_Staff!$B:$B,0)),"")) -> G21126 | P22: =IF(O22="","",IFERROR(INDEX(DB_Staff!$A:$A,MATCH(O22,DB_Staff!$B:$B,0)),"")) | R22: =IF(Q22="","",IFERROR(INDEX(DB_Staff!$A:$A,MATCH(Q22,DB_Staff!$B:$B,0)),""))
A23: BAC-02 | B23: BAC | C23: 2 | D23: P2 | E23: BAC2002 | F23: Tutorial | G23: 2 | H23: 1 | I23: Face-to-face | J23: Seminar Room | K23: ANG HSI LUEI DAPHNE | L23: =IF(K23="","",IFERROR(INDEX(DB_Staff!$A:$A,MATCH(K23,DB_Staff!$B:$B,0)),"")) -> G13857 | N23: =IF(M23="","",IFERROR(INDEX(DB_Staff!$A:$A,MATCH(M23,DB_Staff!$B:$B,0)),"")) | P23: =IF(O23="","",IFERROR(INDEX(DB_Staff!$A:$A,MATCH(O23,DB_Staff!$B:$B,0)),"")) | R23: =IF(Q23="","",IFERROR(INDEX(DB_Staff!$A:$A,MATCH(Q23,DB_Staff!$B:$B,0)),""))
A24: BAC-03 | B24: BAC | C24: 2 | D24: P1 | E24: BAC2005 | F24: Laboratory | G24: 2 | H24: 1 | I24: Face-to-face | J24: Computer Lab | K24: ANG SENG HOCK MARTIN | L24: =IF(K24="","",IFERROR(INDEX(DB_Staff!$A:$A,MATCH(K24,DB_Staff!$B:$B,0)),"")) -> A103460 | M24: ANG SHI LING REGINE | N24: =IF(M24="","",IFERROR(INDEX(DB_Staff!$A:$A,MATCH(M24,DB_Staff!$B:$B,0)),"")) -> H52171 | O24: ANG SHIN YUH | P24: =IF(O24="","",IFERROR(INDEX(DB_Staff!$A:$A,MATCH(O24,DB_Staff!$B:$B,0)),"")) -> A103139 | R24: =IF(Q24="","",IFERROR(INDEX(DB_Staff!$A:$A,MATCH(Q24,DB_Staff!$B:$B,0)),""))
A25: BAC-04 | B25: BAC | C25: 3 | D25: P2 | E25: BAC3003A | F25: Workshop | G25: 1 | H25: 2 | I25: Hybrid | J25: Seminar Room | K25: ANG SIEW LIN AUDREY | L25: =IF(K25="","",IFERROR(INDEX(DB_Staff!$A:$A,MATCH(K25,DB_Staff!$B:$B,0)),"")) -> A102094 | N25: =IF(M25="","",IFERROR(INDEX(DB_Staff!$A:$A,MATCH(M25,DB_Staff!$B:$B,0)),"")) | P25: =IF(O25="","",IFERROR(INDEX(DB_Staff!$A:$A,MATCH(O25,DB_Staff!$B:$B,0)),"")) | R25: =IF(Q25="","",IFERROR(INDEX(DB_Staff!$A:$A,MATCH(Q25,DB_Staff!$B:$B,0)),""))
A26: BAC-05 | B26: BAC | C26: 3 | D26: P1 | E26: BAC3003B | F26: Online | G26: 1 | H26: 1 | I26: Online | J26: Virtual | K26: ANG YOU LING | L26: =IF(K26="","",IFERROR(INDEX(DB_Staff!$A:$A,MATCH(K26,DB_Staff!$B:$B,0)),"")) -> H52219 | N26: =IF(M26="","",IFERROR(INDEX(DB_Staff!$A:$A,MATCH(M26,DB_Staff!$B:$B,0)),"")) | P26: =IF(O26="","",IFERROR(INDEX(DB_Staff!$A:$A,MATCH(O26,DB_Staff!$B:$B,0)),"")) | R26: =IF(Q26="","",IFERROR(INDEX(DB_Staff!$A:$A,MATCH(Q26,DB_Staff!$B:$B,0)),""))
A27: CEG-01 | B27: CEG | C27: 1 | D27: P1 | E27: CEG1007 | F27: Lecture | G27: 2 | H27: 1 | I27: Face-to-face | J27: Lectorial | K27: ANGELA GOH TSE MIN | L27: =IF(K27="","",IFERROR(INDEX(DB_Staff!$A:$A,MATCH(K27,DB_Staff!$B:$B,0)),"")) -> A102296 | M27: ANGELIA TEO KWEE GAIK | N27: =IF(M27="","",IFERROR(INDEX(DB_Staff!$A:$A,MATCH(M27,DB_Staff!$B:$B,0)),"")) -> H52004 | P27: =IF(O27="","",IFERROR(INDEX(DB_Staff!$A:$A,MATCH(O27,DB_Staff!$B:$B,0)),"")) | R27: =IF(Q27="","",IFERROR(INDEX(DB_Staff!$A:$A,MATCH(Q27,DB_Staff!$B:$B,0)),""))
A28: CEG-02 | B28: CEG | C28: 1 | D28: P1 | E28: CEG1009 | F28: Tutorial | G28: 2 | H28: 1 | I28: Face-to-face | J28: Seminar Room | K28: ANITA KRISHNAN-SHANKAR | L28: =IF(K28="","",IFERROR(INDEX(DB_Staff!$A:$A,MATCH(K28,DB_Staff!$B:$B,0)),"")) -> H52313 | N28: =IF(M28="","",IFERROR(INDEX(DB_Staff!$A:$A,MATCH(M28,DB_Staff!$B:$B,0)),"")) | P28: =IF(O28="","",IFERROR(INDEX(DB_Staff!$A:$A,MATCH(O28,DB_Staff!$B:$B,0)),"")) | R28: =IF(Q28="","",IFERROR(INDEX(DB_Staff!$A:$A,MATCH(Q28,DB_Staff!$B:$B,0)),""))
A29: CEG-03 | B29: CEG | C29: 2 | D29: P2 | E29: CEG2005 | F29: Laboratory | G29: 2 | H29: 1 | I29: Face-to-face | J29: Computer Lab | K29: ANNA JANINA BRDULAK | L29: =IF(K29="","",IFERROR(INDEX(DB_Staff!$A:$A,MATCH(K29,DB_Staff!$B:$B,0)),"")) -> H52321 | M29: ANNA KONOPKA | N29: =IF(M29="","",IFERROR(INDEX(DB_Staff!$A:$A,MATCH(M29,DB_Staff!$B:$B,0)),"")) -> G22303 | O29: ANNALENA DANIELS | P29: =IF(O29="","",IFERROR(INDEX(DB_Staff!$A:$A,MATCH(O29,DB_Staff!$B:$B,0)),"")) -> G22336 | R29: =IF(Q29="","",IFERROR(INDEX(DB_Staff!$A:$A,MATCH(Q29,DB_Staff!$B:$B,0)),""))
A30: CEG-04 | B30: CEG | C30: 2 | D30: P1 | E30: CEG2006 | F30: Workshop | G30: 1 | H30: 2 | I30: Hybrid | J30: Seminar Room | K30: ANNE NIEDERDRANK | L30: =IF(K30="","",IFERROR(INDEX(DB_Staff!$A:$A,MATCH(K30,DB_Staff!$B:$B,0)),"")) -> G22224 | N30: =IF(M30="","",IFERROR(INDEX(DB_Staff!$A:$A,MATCH(M30,DB_Staff!$B:$B,0)),"")) | P30: =IF(O30="","",IFERROR(INDEX(DB_Staff!$A:$A,MATCH(O30,DB_Staff!$B:$B,0)),"")) | R30: =IF(Q30="","",IFERROR(INDEX(DB_Staff!$A:$A,MATCH(Q30,DB_Staff!$B:$B,0)),""))
A31: CEG-05 | B31: CEG | C31: 2 | D31: P1 | E31: CEG2009 | F31: Online | G31: 1 | H31: 1 | I31: Online | J31: Virtual | K31: ANNE-SOPHIE DODANTHUN | L31: =IF(K31="","",IFERROR(INDEX(DB_Staff!$A:$A,MATCH(K31,DB_Staff!$B:$B,0)),"")) -> H51862 | N31: =IF(M31="","",IFERROR(INDEX(DB_Staff!$A:$A,MATCH(M31,DB_Staff!$B:$B,0)),"")) | P31: =IF(O31="","",IFERROR(INDEX(DB_Staff!$A:$A,MATCH(O31,DB_Staff!$B:$B,0)),"")) | R31: =IF(Q31="","",IFERROR(INDEX(DB_Staff!$A:$A,MATCH(Q31,DB_Staff!$B:$B,0)),""))
A32: CVE-01 | B32: CVE | C32: 1 | D32: P1 | E32: CVE1222 | F32: Lecture | G32: 2 | H32: 1 | I32: Face-to-face | J32: Lectorial | K32: ARADKAR RUJUTA | L32: =IF(K32="","",IFERROR(INDEX(DB_Staff!$A:$A,MATCH(K32,DB_Staff!$B:$B,0)),"")) -> G22184 | M32: ARCHITA BISWAS | N32: =IF(M32="","",IFERROR(INDEX(DB_Staff!$A:$A,MATCH(M32,DB_Staff!$B:$B,0)),"")) -> A102956 | P32: =IF(O32="","",IFERROR(INDEX(DB_Staff!$A:$A,MATCH(O32,DB_Staff!$B:$B,0)),"")) | R32: =IF(Q32="","",IFERROR(INDEX(DB_Staff!$A:$A,MATCH(Q32,DB_Staff!$B:$B,0)),""))
A33: CVE-02 | B33: CVE | C33: 1 | D33: P2 | E33: CVE1242 | F33: Tutorial | G33: 2 | H33: 1 | I33: Face-to-face | J33: Seminar Room | K33: ARNOLD CHRISTOPHER JOHN | L33: =IF(K33="","",IFERROR(INDEX(DB_Staff!$A:$A,MATCH(K33,DB_Staff!$B:$B,0)),"")) -> A103277 | N33: =IF(M33="","",IFERROR(INDEX(DB_Staff!$A:$A,MATCH(M33,DB_Staff!$B:$B,0)),"")) | P33: =IF(O33="","",IFERROR(INDEX(DB_Staff!$A:$A,MATCH(O33,DB_Staff!$B:$B,0)),"")) | R33: =IF(Q33="","",IFERROR(INDEX(DB_Staff!$A:$A,MATCH(Q33,DB_Staff!$B:$B,0)),""))
A34: CVE-03 | B34: CVE | C34: 1 | D34: P1 | E34: CVE1261 | F34: Laboratory | G34: 2 | H34: 1 | I34: Face-to-face | J34: Computer Lab | K34: ASIF USMANI | L34: =IF(K34="","",IFERROR(INDEX(DB_Staff!$A:$A,MATCH(K34,DB_Staff!$B:$B,0)),"")) -> G22098 | M34: ASILA ALIA D/O KO NOORDIN | N34: =IF(M34="","",IFERROR(INDEX(DB_Staff!$A:$A,MATCH(M34,DB_Staff!$B:$B,0)),"")) -> H51984 | O34: ASNAH BINTE AHMAD | P34: =IF(O34="","",IFERROR(INDEX(DB_Staff!$A:$A,MATCH(O34,DB_Staff!$B:$B,0)),"")) -> H51412 | R34: =IF(Q34="","",IFERROR(INDEX(DB_Staff!$A:$A,MATCH(Q34,DB_Staff!$B:$B,0)),""))
A35: CVE-04 | B35: CVE | C35: 3 | D35: P2 | E35: CVE3221 | F35: Workshop | G35: 1 | H35: 2 | I35: Hybrid | J35: Seminar Room | K35: AU YOKE MAY | L35: =IF(K35="","",IFERROR(INDEX(DB_Staff!$A:$A,MATCH(K35,DB_Staff!$B:$B,0)),"")) -> H50262 | N35: =IF(M35="","",IFERROR(INDEX(DB_Staff!$A:$A,MATCH(M35,DB_Staff!$B:$B,0)),"")) | P35: =IF(O35="","",IFERROR(INDEX(DB_Staff!$A:$A,MATCH(O35,DB_Staff!$B:$B,0)),"")) | R35: =IF(Q35="","",IFERROR(INDEX(DB_Staff!$A:$A,MATCH(Q35,DB_Staff!$B:$B,0)),""))
A36: CVE-05 | B36: CVE | C36: 3 | D36: P1 | E36: CVE3222 | F36: Online | G36: 1 | H36: 1 | I36: Online | J36: Virtual | K36: AVNIT KARIN | L36: =IF(K36="","",IFERROR(INDEX(DB_Staff!$A:$A,MATCH(K36,DB_Staff!$B:$B,0)),"")) -> A88280 | N36: =IF(M36="","",IFERROR(INDEX(DB_Staff!$A:$A,MATCH(M36,DB_Staff!$B:$B,0)),"")) | P36: =IF(O36="","",IFERROR(INDEX(DB_Staff!$A:$A,MATCH(O36,DB_Staff!$B:$B,0)),"")) | R36: =IF(Q36="","",IFERROR(INDEX(DB_Staff!$A:$A,MATCH(Q36,DB_Staff!$B:$B,0)),""))
A37: DSC-01 | B37: DSC | C37: 1 | D37: P1 | E37: DSC1001 | F37: Lecture | G37: 2 | H37: 1 | I37: Face-to-face | J37: Lectorial | K37: AW MEIFANG SHELEEN | L37: =IF(K37="","",IFERROR(INDEX(DB_Staff!$A:$A,MATCH(K37,DB_Staff!$B:$B,0)),"")) -> H50565 | M37: AWAD AWAD MOHAMED KHIRELDIN | N37: =IF(M37="","",IFERROR(INDEX(DB_Staff!$A:$A,MATCH(M37,DB_Staff!$B:$B,0)),"")) -> A101565 | P37: =IF(O37="","",IFERROR(INDEX(DB_Staff!$A:$A,MATCH(O37,DB_Staff!$B:$B,0)),"")) | R37: =IF(Q37="","",IFERROR(INDEX(DB_Staff!$A:$A,MATCH(Q37,DB_Staff!$B:$B,0)),""))
A38: DSC-02 | B38: DSC | C38: 2 | D38: P1 | E38: DSC2203 | F38: Tutorial | G38: 2 | H38: 1 | I38: Face-to-face | J38: Seminar Room | K38: AZHAR BIN ABDUL SALAM | L38: =IF(K38="","",IFERROR(INDEX(DB_Staff!$A:$A,MATCH(K38,DB_Staff!$B:$B,0)),"")) -> H51896 | N38: =IF(M38="","",IFERROR(INDEX(DB_Staff!$A:$A,MATCH(M38,DB_Staff!$B:$B,0)),"")) | P38: =IF(O38="","",IFERROR(INDEX(DB_Staff!$A:$A,MATCH(O38,DB_Staff!$B:$B,0)),"")) | R38: =IF(Q38="","",IFERROR(INDEX(DB_Staff!$A:$A,MATCH(Q38,DB_Staff!$B:$B,0)),""))
A39: DSC-03 | B39: DSC | C39: 2 | D39: P2 | E39: DSC2302 | F39: Laboratory | G39: 2 | H39: 1 | I39: Face-to-face | J39: Computer Lab | K39: BALA SUBRAMANIAM MAHARANI | L39: =IF(K39="","",IFERROR(INDEX(DB_Staff!$A:$A,MATCH(K39,DB_Staff!$B:$B,0)),"")) -> G22287 | M39: BALAPANURU JANARDHAN | N39: =IF(M39="","",IFERROR(INDEX(DB_Staff!$A:$A,MATCH(M39,DB_Staff!$B:$B,0)),"")) -> A103829 | O39: BALWANT SINGH | P39: =IF(O39="","",IFERROR(INDEX(DB_Staff!$A:$A,MATCH(O39,DB_Staff!$B:$B,0)),"")) -> H52022 | R39: =IF(Q39="","",IFERROR(INDEX(DB_Staff!$A:$A,MATCH(Q39,DB_Staff!$B:$B,0)),""))
A40: DSC-04 | B40: DSC | C40: 3 | D40: P1 | E40: DSC3002B | F40: Workshop | G40: 1 | H40: 2 | I40: Hybrid | J40: Seminar Room | K40: BANAGUAS GLENN SUERTE FELIPE | L40: =IF(K40="","",IFERROR(INDEX(DB_Staff!$A:$A,MATCH(K40,DB_Staff!$B:$B,0)),"")) -> H51947 | N40: =IF(M40="","",IFERROR(INDEX(DB_Staff!$A:$A,MATCH(M40,DB_Staff!$B:$B,0)),"")) | P40: =IF(O40="","",IFERROR(INDEX(DB_Staff!$A:$A,MATCH(O40,DB_Staff!$B:$B,0)),"")) | R40: =IF(Q40="","",IFERROR(INDEX(DB_Staff!$A:$A,MATCH(Q40,DB_Staff!$B:$B,0)),""))
...

Sheet Remarks_(optional)
A1: Requirement ID | B1: Start Week | C1: End Week | D1: Week Pattern | E1: Custom Weeks | F1: Preferred Days | G1: Avoid Days | H1: Fixed Day | I1: Fixed Start Time | J1: Fixed End Time | K1: Remarks
A2: AAI-01 | B2: 1 | C2: 13 | D2: Weekly | F2: Tuesday,Thursday | H2: Monday | I2: 09:00 | J2: 11:00 | K2: Large cohort anchor lecture.
A3: AAI-02 | B3: 1 | C3: 13 | D3: Odd | F3: Tuesday,Thursday | G3: Friday | K3: Tutorial split; suitable for repeated group scheduling.
A4: AAI-03 | B4: 1 | C4: 13 | D4: Custom | E4: 3,6,9,12 | F4: Tuesday,Thursday | G4: Friday | K4: Custom teaching weeks for lab rotations.
A5: AAI-04 | B5: 1 | C5: 13 | D5: Weekly | F5: Tuesday,Thursday | K5: Two workshop meetings per week request.
A6: AAI-05 | B6: 1 | C6: 13 | D6: Weekly | F6: Monday,Tuesday | K6: Online asynchronous/synchronous component.
A7: ACC-01 | B7: 1 | C7: 13 | D7: Weekly | F7: Tuesday,Thursday | H7: Tuesday | I7: 10:00 | J7: 12:00 | K7: Large cohort anchor lecture.
A8: ACC-02 | B8: 1 | C8: 13 | D8: Even | F8: Tuesday,Thursday | G8: Friday | K8: Tutorial split; suitable for repeated group scheduling.
A9: ACC-03 | B9: 1 | C9: 13 | D9: Custom | E9: 3,6,9,12 | F9: Tuesday,Thursday | G9: Friday | K9: Custom teaching weeks for lab rotations.
A10: ACC-04 | B10: 1 | C10: 13 | D10: Weekly | F10: Tuesday,Thursday | K10: Two workshop meetings per week request.
A11: ACC-05 | B11: 1 | C11: 13 | D11: Weekly | F11: Monday,Tuesday | K11: Online asynchronous/synchronous component.
A12: ASE-01 | B12: 1 | C12: 13 | D12: Weekly | F12: Tuesday,Thursday | H12: Wednesday | I12: 11:00 | J12: 13:00 | K12: Large cohort anchor lecture.
A13: ASE-02 | B13: 1 | C13: 13 | D13: Even | F13: Tuesday,Thursday | G13: Friday | K13: Tutorial split; suitable for repeated group scheduling.
A14: ASE-03 | B14: 1 | C14: 13 | D14: Custom | E14: 3,6,9,12 | F14: Tuesday,Thursday | G14: Friday | K14: Custom teaching weeks for lab rotations.
A15: ASE-04 | B15: 1 | C15: 13 | D15: Weekly | F15: Tuesday,Thursday | K15: Two workshop meetings per week request.
A16: ASE-05 | B16: 1 | C16: 13 | D16: Weekly | F16: Monday,Tuesday | K16: Online asynchronous/synchronous component.
A17: ATM-01 | B17: 1 | C17: 13 | D17: Weekly | F17: Tuesday,Thursday | H17: Thursday | I17: 13:00 | J17: 15:00 | K17: Large cohort anchor lecture.
A18: ATM-02 | B18: 1 | C18: 13 | D18: Even | F18: Tuesday,Thursday | G18: Friday | K18: Tutorial split; suitable for repeated group scheduling.
A19: ATM-03 | B19: 1 | C19: 13 | D19: Custom | E19: 3,6,9,12 | F19: Tuesday,Thursday | G19: Friday | K19: Custom teaching weeks for lab rotations.
A20: ATM-04 | B20: 1 | C20: 13 | D20: Weekly | F20: Tuesday,Thursday | K20: Two workshop meetings per week request.
A21: ATM-05 | B21: 1 | C21: 13 | D21: Weekly | F21: Monday,Tuesday | K21: Online asynchronous/synchronous component.
A22: BAC-01 | B22: 1 | C22: 13 | D22: Weekly | F22: Tuesday,Thursday | H22: Friday | I22: 14:00 | J22: 16:00 | K22: Large cohort anchor lecture.
A23: BAC-02 | B23: 1 | C23: 13 | D23: Odd | F23: Tuesday,Thursday | G23: Friday | K23: Tutorial split; suitable for repeated group scheduling.
A24: BAC-03 | B24: 1 | C24: 13 | D24: Custom | E24: 3,6,9,12 | F24: Tuesday,Thursday | G24: Friday | K24: Custom teaching weeks for lab rotations.
A25: BAC-04 | B25: 1 | C25: 13 | D25: Weekly | F25: Tuesday,Thursday | K25: Two workshop meetings per week request.
A26: BAC-05 | B26: 1 | C26: 13 | D26: Weekly | F26: Monday,Tuesday | K26: Online asynchronous/synchronous component.
A27: CEG-01 | B27: 1 | C27: 13 | D27: Weekly | F27: Tuesday,Thursday | H27: Monday | I27: 09:00 | J27: 11:00 | K27: Large cohort anchor lecture.
A28: CEG-02 | B28: 1 | C28: 13 | D28: Even | F28: Tuesday,Thursday | G28: Friday | K28: Tutorial split; suitable for repeated group scheduling.
A29: CEG-03 | B29: 1 | C29: 13 | D29: Custom | E29: 3,6,9,12 | F29: Tuesday,Thursday | G29: Friday | K29: Custom teaching weeks for lab rotations.
A30: CEG-04 | B30: 1 | C30: 13 | D30: Weekly | F30: Tuesday,Thursday | K30: Two workshop meetings per week request.
A31: CEG-05 | B31: 1 | C31: 13 | D31: Weekly | F31: Monday,Tuesday | K31: Online asynchronous/synchronous component.
A32: CVE-01 | B32: 1 | C32: 13 | D32: Weekly | F32: Tuesday,Thursday | H32: Tuesday | I32: 10:00 | J32: 12:00 | K32: Large cohort anchor lecture.
A33: CVE-02 | B33: 1 | C33: 13 | D33: Even | F33: Tuesday,Thursday | G33: Friday | K33: Tutorial split; suitable for repeated group scheduling.
A34: CVE-03 | B34: 1 | C34: 13 | D34: Custom | E34: 3,6,9,12 | F34: Tuesday,Thursday | G34: Friday | K34: Custom teaching weeks for lab rotations.
A35: CVE-04 | B35: 1 | C35: 13 | D35: Weekly | F35: Tuesday,Thursday | K35: Two workshop meetings per week request.
A36: CVE-05 | B36: 1 | C36: 13 | D36: Weekly | F36: Monday,Tuesday | K36: Online asynchronous/synchronous component.
A37: DSC-01 | B37: 1 | C37: 13 | D37: Weekly | F37: Tuesday,Thursday | H37: Wednesday | I37: 11:00 | J37: 13:00 | K37: Large cohort anchor lecture.
A38: DSC-02 | B38: 1 | C38: 13 | D38: Even | F38: Tuesday,Thursday | G38: Friday | K38: Tutorial split; suitable for repeated group scheduling.
A39: DSC-03 | B39: 1 | C39: 13 | D39: Custom | E39: 3,6,9,12 | F39: Tuesday,Thursday | G39: Friday | K39: Custom teaching weeks for lab rotations.
A40: DSC-04 | B40: 1 | C40: 13 | D40: Weekly | F40: Tuesday,Thursday | K40: Two workshop meetings per week request.
...

Sheet DB_Staff
A1: staff_id | B1: staff_name
A2: G22207 | B2: AARON TAN
A3: H50949 | B3: AARON YEO SULUN
A4: H50641 | B4: ABDUL HAMID BIN ABDULLAH
A5: H52030 | B5: ABDUL JABBAR ABDULLAH
A6: G22059 | B6: ABEL TAN
A7: G22353 | B7: ABI SAN
A8: A101849 | B8: ABID ALI
A9: H51758 | B9: ABIGAIL ELIZABETH ROCHE
A10: A103173 | B10: ABROL AKSHITA
A11: A101516 | B11: ADRIEL YEO CI LIN
A12: A101170 | B12: AFIDA BINTE ABDUL RAHIM
... A74: H52219 | B74: ANG YOU LING
B75: ANG YUN MEI
A76: A101642 | B76: ANG YUN MEI, ELISA
A77: G15808 | B77: ANGELA CHONG
A78: A102296 | B78: ANGELA GOH TSE MIN
A79: H52004 | B79: ANGELIA TEO KWEE GAIK
A80: H51918 | B80: ANGELINE WONG PEI SZE
A81: H52313 | B81: ANITA KRISHNAN-SHANKAR
A82: G22186 | B82: ANKESH JAIN
A83: G22067 | B83: ANN MONAGHAN
A84: H52321 | B84: ANNA JANINA BRDULAK
A85: G22303 | B85: ANNA KONOPKA
A86: G22336 | B86: ANNALENA DANIELS
A87: G22224 | B87: ANNE NIEDERDRANK
... A102: H50262 | B102: AU YOKE MAY
B103: AUDREY ANG SIEW LIN
A104: A100300 | B104: AUDREY JOHN BENEDICT
A105: H51793 | B105: AUDREY LEE JIA YI
A106: A88280 | B106: AVNIT KARIN
B107: AW KOK SENG
A108: A102669 | B108: AW KOK SENG (HU GUOCHENG)
A109: H52300 | B109: AW KUAN THAI
A110: H50565 | B110: AW MEIFANG SHELEEN
A111: A101565 | B111: AWAD AWAD MOHAMED KHIRELDIN
A112: A102350 | B112: AYYALUSAMY VIJAYAKUMAR
A113: H51896 | B113: AZHAR BIN ABDUL SALAM
A114: H50608 | B114: AZIZAH BINTE MOHAMED AFIF
A115: A101489 | B115: AZZALIA BINTE ABU
...

Sheet DB_Programme
A1: code | B1: name | C1: years
A2: AAI | B2: Applied Artificial Intelligence | C2: 3
A3: ACC | B3: Accountancy | C3: 3
A4: ASE | B4: Aircraft Systems Engineering | C4: 3
A5: ATM | B5: Aviation Management | C5: 3
A6: BAC | B6: Applied Computing / Applied Computing (Fintech) | C6: 3
A7: BICT | B7: Business and Infocomm Technology | C7: 4
A8: CDM | B8: Communication and Digital Media | C8: 3
A9: CEG | B9: Computer Engineering | C9: 3
A10: CVE | B10: Civil Engineering | C10: 4
A11: DSC | B11: Digital Supply Chain | C11: 3
A12: EDE | B12: Electronics and Data Engineering | C12: 4
A13: EEE | B13: Electrical and Electronic Engineering | C13: 4
... A28: TCE | B28: Chemical Engineering - likely TUM Chemical Engineering prefix | C28: 4

Sheet DB_Modules
A1: module_code
A2: AAI1001
A3: AAI2002
A4: AAI3008
A5: AAI4001
A6: AAI4002A
A7: AAI4002B
A8: ACC1023
A9: ACC1024
A10: ACC1025
A11: ACC1026
A12: ACC3001A
... A557: UXG4990

Sheet DB_Options
A1: class_type | B1: delivery_mode | C1: venue_type | D1: group_code | E1: year
A2: Lecture | B2: Face-to-face | C2: Lectorial | D2: P1 | E2: 1
A3: Tutorial | B3: Hybrid | C3: Seminar Room | D3: P2 | E3: 2
A4: Laboratory | B4: Online | C4: Computer Lab | D4: P3 | E4: 3
A5: Workshop | C5: Virtual | D5: P4 | E5: 4
A6: Online | D6: P5
A7: Quiz
